Workbook

Sheet DOMESTIC DEBIT
A2: Domestic Air Travel Statement for the period 16-08-2026 to 31-08-2026
A3: Reference No. | B3: Reference Date | C3: Booking Date | D3: Department | E3: Location | F3: Passenger Name | G3: Employee Code | H3: Cost Center | I3: Cost Code | J3: Product Line | K3: Travel Date | L3: Sector | M3: Airline | N3: Flight No. | O3: Class | P3: Ticket No. | Q3: Taxable Fare | R3: Exempt Fare | S3: Other Taxes | T3: Airline GST | U3: Total Fare | V3: Travel Management Fee | W3: Approver Name | X3: Approval Status | Y3: Approval Date | Z3: Approval Time | AA3: Flown Status | AB3: Corporate | AC3: Business Unit | AD3: Booking Reference No. | AE3: Trip Unique ID | AF3: Designation | AG3: Type Of Journey | AH3: Type Of Travel | AI3: Job Band | AJ3: Passenger Email Id | AK3: Booking Code | AL3: YQ | AM3: YR | AN3: Request No. | AO3: Request Created Date | AP3: Request Created Time | AQ3: Trip Title | AR3: Fare Type | AS3: Purpose of Visit | AT3: Reissue Status | AU3: Second Approver Name | AV3: Second Approval Status | AW3: Second Approval Date | AX3: Second Approval Time | AY3: Contact No. | AZ3: GST No. | BA3: GST State | BB3: Full Ticket No. | BC3: Airline PNR | BD3: XL Code | BE3: Project | BF3: HSN Code | BG3: Only Travel Date | BH3: Requester Name | BI3: Requester Empid | BJ3: KMS | BK3: Client Req No | BL3: AIR IGST | BM3: AIR CGST | BN3: AIR SGST | BO3: Carbon Emission (Metric Tonnes) | BP3: Arrival Date | BQ3: Event Name | BR3: TR ID | BS3: Debit Cost Code | BT3: Function | BU3: PLANNED_TIME_IN_DAYS | BV3: Source Destination City | BW3: Referred by | BX3: GL Code | BY3: Job Type | BZ3: Division Name | CA3: K3 | CB3: SAP / HR Company Code | CC3: Adani Legal Entity GST Number | CD3: Location Code | CE3: Gender | CF3: Unique ID | CG3: Job Reason | CH3: CC_AUTHCODE | CI3: Zone | CJ3: FIRST_APP_emp_id | CK3: FIRST_APP_mgmtl_name | CL3: SECOND_APP_emp_id | CM3: SECOND_APP_mgmtl_name
A4: DW26/780819 | B4: 16-AUG-2026 | C4: 16-AUG-2026 | D4: Administration | E4: Delhi | F4: MR. M A SIKANDAR | G4: CQ00873075 | H4: NA | I4: NA | K4: 22-08-2026 22:45:00 | L4: Kannur-New Delhi | M4: Indigo | N4: 6E-6148 | O4: Economy | P4: DBS17D | Q4: 17160 | R4: 0 | S4: 1432 | T4: 858 | U4: 19450 | V4: 75 | W4: MS. PRIYANKA THAKUR | X4: Approved | Y4: 16-AUG-2026 | Z4: 12:06 | AA4: FLOWN | AB4: Teamlease Services Ltd | AC4: TLEdtech | AD4: 200117939470 | AE4: 7582415 | AF4: Consultant | AG4: Round Trip | AH4: Domestic | AI4: Consultant | AJ4: masikandar@jamiahamdard.ac.in | AK4: H | AL4: 800 | AM4: 0 | AN4: 44715644 | AO4: 16-AUG-2026 | AP4: 11:56 | AR4: CORPORATE | AS4: Official | AT4: Original | AY4: 9818798949 | AZ4: 27AAPCS2871R1ZB | BA4: Maharashtra | BB4: DBS17D | BC4: DBS17D | BD4: T004S | BE4: - | BF4: 996425 | BG4: 22-08-202/ | BH4: Mr. Satyavan Sawant | BI4: T17247 | BJ4: 1858 | BL4: 858 | BM4: 0 | BN4: 0 | BO4: 0.2952362 | BP4: 23-08-2026 01:45:00 | BU4: 6 | BV4: CNN-DEL | CA4: 858 | CB4: TeamLease Edtech Limited | CC4: 27AAPCS2871R1ZB | CE4: M | CF4: '11793947008222245 | CJ4: T16868 | CK4: L3
A5: DW26/782230 | B5: 16-AUG-2026 | C5: 16-AUG-2026 | D5: Administration | E5: Delhi | F5: MR. ABDUL FAROOQI | G5: CQ00873076 | H5: NA | I5: NA | K5: 22-08-2026 22:45:00 | L5: Kannur-New Delhi | M5: Indigo | N5: 6E-6148 | O5: Economy | P5: ZD8CPG | Q5: 17160 | R5: 0 | S5: 1432 | T5: 858 | U5: 19450 | V5: 75 | W5: MS. PRIYANKA THAKUR | X5: Approved | Y5: 16-AUG-2026 | Z5: 12:06 | AA5: RFND | AB5: Teamlease Services Ltd | AC5: TLEdtech | AD5: 200117939474 | AE5: 7582416 | AF5: Consultant | AG5: Round Trip | AH5: Domestic | AI5: Consultant | AJ5: majid@jamiahamdard.ac.in | AK5: H | AL5: 800 | AM5: 0 | AN5: 44715674 | AO5: 16-AUG-2026 | AP5: 12:00 | AR5: CORPORATE | AS5: Official | AT5: Original | AY5: 9891958565 | AZ5: 27AAPCS2871R1ZB | BA5: Maharashtra | BB5: ZD8CPG | BC5: ZD8CPG | BD5: T004S | BE5: - | BF5: 996425 | BG5: 22-08-202/ | BH5: Mr. Satyavan Sawant | BI5: T17247 | BJ5: 1858 | BL5: 858 | BM5: 0 | BN5: 0 | BO5: 0.2952362 | BP5: 23-08-2026 01:45:00 | BU5: 6 | BV5: CNN-DEL | CA5: 858 | CB5: TeamLease Edtech Limited | CC5: 27AAPCS2871R1ZB | CE5: M | CF5: '11793947408222245 | CJ5: T16868 | CK5: L3
A6: DW26/781796 | B6: 16-AUG-2026 | C6: 16-AUG-2026 | D6: Administration | E6: Delhi | F6: MR. ABDUL FAROOQI | G6: CQ00873076 | H6: NA | I6: NA | K6: 19-08-2026 09:30:00/19-08-2026 13:35:00 | L6: New Delhi-Mumbai/Mumbai-Kannur | M6: Indigo/Indigo | N6: 6E-6107/6E-2011 | O6: Economy | P6: SH8JWH | Q6: 9800 | R6: 0 | S6: 382 | T6: 490 | U6: 10672 | V6: 150 | W6: MS. PRIYANKA THAKUR | X6: Approved | Y6: 16-AUG-2026 | Z6: 12:06 | AA6: RFND/RFND | AB6: Teamlease Services Ltd | AC6: TLEdtech | AD6: 200117939473 | AE6: 7582416 | AF6: Consultant | AG6: Round Trip | AH6: Domestic | AI6: Consultant | AJ6: majid@jamiahamdard.ac.in | AK6: R/R | AL6: 1000 | AM6: 0 | AN6: 44715674 | AO6: 16-AUG-2026 | AP6: 12:00 | AR6: CORPORATE | AS6: Official | AT6: Original | AY6: 9891958565 | AZ6: 27AAPCS2871R1ZB | BA6: Maharashtra | BB6: SH8JWH | BC6: SH8JWH | BD6: T004S | BE6: - | BF6: 996425 | BG6: 19-08-202//19-08-20 | BH6: Mr. Satyavan Sawant | BI6: T17247 | BJ6: 1139/848 | BL6: 490 | BM6: 0 | BN6: 0 | BO6: 0.3157343 | BP6: 19-08-2026 11:55:00/19-08-2026 15:15:00 | BU6: 3 | BV6: DEL-CNN | CA6: 490 | CB6: TeamLease Edtech Limited | CC6: 27AAPCS2871R1ZB | CE6: M | CF6: '11793947308190930/11793947308191335 | CJ6: T16868 | CK6: L3
A7: DW26/780892 | B7: 16-AUG-2026 | C7: 16-AUG-2026 | D7: Administration | E7: Delhi | F7: MR. M A SIKANDAR | G7: CQ00873075 | H7: NA | I7: NA | K7: 19-08-2026 09:30:00/19-08-2026 13:35:00 | L7: New Delhi-Mumbai/Mumbai-Kannur | M7: Indigo/Indigo | N7: 6E-6107/6E-2011 | O7: Economy | P7: EBE7FG | Q7: 9800 | R7: 0 | S7: 382 | T7: 490 | U7: 10672 | V7: 150 | W7: MS. PRIYANKA THAKUR | X7: Approved | Y7: 16-AUG-2026 | Z7: 12:06 | AA7: FLOWN/FLOWN | AB7: Teamlease Services Ltd | AC7: TLEdtech | AD7: 200117939469 | AE7: 7582415 | AF7: Consultant | AG7: Round Trip | AH7: Domestic | AI7: Consultant | AJ7: masikandar@jamiahamdard.ac.in | AK7: R/R | AL7: 1000 | AM7: 0 | AN7: 44715644 | AO7: 16-AUG-2026 | AP7: 11:56 | AR7: CORPORATE | AS7: Official | AT7: Original | AY7: 9818798949 | AZ7: 27AAPCS2871R1ZB | BA7: Maharashtra | BB7: EBE7FG | BC7: EBE7FG | BD7: T004S | BE7: - | BF7: 996425 | BG7: 19-08-202//19-08-20 | BH7: Mr. Satyavan Sawant | BI7: T17247 | BJ7: 1139/848 | BL7: 490 | BM7: 0 | BN7: 0 | BO7: 0.3157343 | BP7: 19-08-2026 11:55:00/19-08-2026 15:15:00 | BU7: 3 | BV7: DEL-CNN | CA7: 490 | CB7: TeamLease Edtech Limited | CC7: 27AAPCS2871R1ZB | CE7: M | CF7: '11793946908190930/11793946908191335 | CJ7: T16868 | CK7: L3
A8: DW26/782006 | B8: 16-AUG-2026 | C8: 16-AUG-2026 | D8: University B2C | E8: Bengaluru | F8: MR. CHETAN DIXIT | G8: SG0506 | H8: 3701618 | I8: 62-MUM-SSS | K8: 19-08-2026 09:30:00/19-08-2026 13:35:00 | L8: New Delhi-Mumbai/Mumbai-Kannur | M8: Indigo/Indigo | N8: 6E-6107/6E-2011 | O8: Economy | P8: W662SL | Q8: 10620 | R8: 0 | S8: 702 | T8: 531 | U8: 11853 | V8: 150 | W8: MR. UDITENDU BOSE | X8: Approved | Y8: 16-AUG-2026 | Z8: 16:43 | AA8: FLOWN/FLOWN | AB8: Teamlease Services Ltd | AC8: TLEdtech | AD8: 200117942128 | AE8: 1388660 | AF8: Vertical Head - Consumer Business | AG8: Round Trip | AH8: Domestic | AI8: L9 | AJ8: chetan.dixit@teamlease.com | AK8: Q/Q | AL8: 1000 | AM8: 0 | AN8: 44718713 | AO8: 16-AUG-2026 | AP8: 16:38 | AR8: CORPORATE | AS8: Official | AT8: Original | AY8: 9811525485 | AZ8: 29AAPCS2871R1Z7 | BA8: Karnataka | BB8: W662SL | BC8: W662SL | BD8: T004S | BE8: - | BF8: 996425 | BG8: 19-08-202//19-08-20 | BH8: Mr. Satyavan Sawant | BI8: T17247 | BJ8: 1139/848 | BL8: 531 | BM8: 0 | BN8: 0 | BO8: 0.3157343 | BP8: 19-08-2026 11:55:00/19-08-2026 15:15:00 | BU8: 3 | BV8: DEL-CNN | CA8: 531 | CB8: TeamLease Edtech Limited | CC8: 29AAPCS2871R1Z7 | CE8: M | CF8: '11794212808190930/11794212808191335 | CJ8: SG0320 | CK8: L10
A9: DW26/780625 | B9: 16-AUG-2026 | C9: 16-AUG-2026 | D9: University B2C | E9: Bengaluru | F9: MR. CHETAN DIXIT | G9: SG0506 | H9: 3701618 | I9: 62-MUM-SSS | K9: 22-08-2026 22:45:00 | L9: Kannur-New Delhi | M9: Indigo | N9: 6E-6148 | O9: Economy | P9: A72B5C | Q9: 17160 | R9: 0 | S9: 1786 | T9: 858 | U9: 19804 | V9: 75 | W9: MR. UDITENDU BOSE | X9: Approved | Y9: 16-AUG-2026 | Z9: 16:43 | AA9: FLOWN | AB9: Teamlease Services Ltd | AC9: TLEdtech | AD9: 200117942129 | AE9: 1388660 | AF9: Vertical Head - Consumer Business | AG9: Round Trip | AH9: Domestic | AI9: L9 | AJ9: chetan.dixit@teamlease.com | AK9: H | AL9: 800 | AM9: 0 | AN9: 44718713 | AO9: 16-AUG-2026 | AP9: 16:38 | AR9: CORPORATE | AS9: Official | AT9: Original | AY9: 9811525485 | AZ9: 29AAPCS2871R1Z7 | BA9: Karnataka | BB9: A72B5C | BC9: A72B5C | BD9: T004S | BE9: - | BF9: 996425 | BG9: 22-08-202/ | BH9: Mr. Satyavan Sawant | BI9: T17247 | BJ9: 1858 | BL9: 858 | BM9: 0 | BN9: 0 | BO9: 0.2952362 | BP9: 23-08-2026 01:45:00 | BU9: 6 | BV9: CNN-DEL | CA9: 858 | CB9: TeamLease Edtech Limited | CC9: 29AAPCS2871R1Z7 | CE9: M | CF9: '11794212908222245 | CJ9: SG0320 | CK9: L10
A10: DW26/781991 | B10: 16-AUG-2026 | C10: 16-AUG-2026 | D10: Administration | E10: Delhi | F10: MR. ABDUL MAJID FAROOQI | G10: CQ00873076 | H10: NA | I10: NA | K10: 19-08-2026 09:30:00/19-08-2026 13:35:00 | L10: New Delhi-Mumbai/Mumbai-Kannur | M10: Indigo/Indigo | N10: 6E-6107/6E-2011 | O10: Economy | P10: VHYEPH | Q10: 10620 | R10: 0 | S10: 389 | T10: 531 | U10: 11540 | V10: 150 | W10: MS. PRIYANKA THAKUR | X10: Approved | Y10: 16-AUG-2026 | Z10: 16:47 | AA10: FLOWN/FLOWN | AB10: Teamlease Services Ltd | AC10: TLEdtech | AD10: 200117942152 | AE10: 7582416 | AF10: Consultant | AG10: Round Trip | AH10: Domestic | AI10: Consultant | AJ10: majid@jamiahamdard.ac.in | AK10: Q/Q | AL10: 1000 | AM10: 0 | AN10: 44718750 | AO10: 16-AUG-2026 | AP10: 16:43 | AR10: CORPORATE | AS10: Official | AT10: Original | AY10: 9891958565 | AZ10: 27AAPCS2871R1ZB | BA10: Maharashtra | BB10: VHYEPH | BC10: VHYEPH | BD10: T004S | BE10: - | BF10: 996425 | BG10: 19-08-202//19-08-20 | BH10: Mr. Satyavan Sawant | BI10: T17247 | BJ10: 1139/848 | BL10: 531 | BM10: 0 | BN10: 0 | BO10: 0.3157343 | BP10: 19-08-2026 11:55:00/19-08-2026 15:15:00 | BU10: 3 | BV10: DEL-CNN | CA10: 531 | CB10: TeamLease Edtech Limited | CC10: 27AAPCS2871R1ZB | CE10: M | CF10: '11794215208190930/11794215208191335 | CJ10: T16868 | CK10: L3
A11: DW26/781403 | B11: 16-AUG-2026 | C11: 16-AUG-2026 | D11: Administration | E11: Delhi | F11: MR. ABDUL MAJID FAROOQI | G11: CQ00873076 | H11: NA | I11: NA | K11: 22-08-2026 22:45:00 | L11: Kannur-New Delhi | M11: Indigo | N11: 6E-6148 | O11: Economy | P11: MBF3YJ | Q11: 17160 | R11: 0 | S11: 1432 | T11: 858 | U11: 19450 | V11: 75 | W11: MS. PRIYANKA THAKUR | X11: Approved | Y11: 16-AUG-2026 | Z11: 16:47 | AA11: FLOWN | AB11: Teamlease Services Ltd | AC11: TLEdtech | AD11: 200117942153 | AE11: 7582416 | AF11: Consultant | AG11: Round Trip | AH11: Domestic | AI11: Consultant | AJ11: majid@jamiahamdard.ac.in | AK11: H | AL11: 800 | AM11: 0 | AN11: 44718750 | AO11: 16-AUG-2026 | AP11: 16:43 | AR11: CORPORATE | AS11: Official | AT11: Original | AY11: 9891958565 | AZ11: 27AAPCS2871R1ZB | BA11: Maharashtra | BB11: MBF3YJ | BC11: MBF3YJ | BD11: T004S | BE11: - | BF11: 996425 | BG11: 22-08-202/ | BH11: Mr. Satyavan Sawant | BI11: T17247 | BJ11: 1858 | BL11: 858 | BM11: 0 | BN11: 0 | BO11: 0.2952362 | BP11: 23-08-2026 01:45:00 | BU11: 6 | BV11: CNN-DEL | CA11: 858 | CB11: TeamLease Edtech Limited | CC11: 27AAPCS2871R1ZB | CE11: M | CF11: '11794215308222245 | CJ11: T16868 | CK11: L3
A12: DW26/785455 | B12: 17-AUG-2026 | C12: 17-AUG-2026 | D12: Leadership | E12: Bengaluru | F12: MR. SHANTANU ROOJ | G12: SG0014 | H12: 3701618 | I12: 68-MUM-LED | K12: 26-08-2026 07:45:00 | L12: Mumbai-Kolkata | M12: Indigo | N12: 6E-5329 | O12: Economy | P12: K6J34F | Q12: 7920 | R12: 0 | S12: 440 | T12: 396 | U12: 8756 | V12: 0 | W12: MR. SHANTANU ROOJ | X12: Approved | Y12: 17-AUG-2026 | Z12: 15:11 | AA12: RFND | AB12: Teamlease Services Ltd | AC12: TLEdtech | AD12: 200117956566 | AE12: 1388000 | AF12: Founder and CEO | AG12: Round Trip | AH12: Domestic | AI12: LST | AJ12: shantanu@teamlease.com | AK12: Q | AL12: 800 | AM12: 0 | AN12: 44739307 | AO12: 17-AUG-2026 | AP12: 14:38 | AR12: CORPORATE | AS12: Official | AT12: Original | AY12: 9870333111 | AZ12: 29AAPCS2871R1Z7 | BA12: Karnataka | BB12: K6J34F | BC12: K6J34F | BD12: T004S | BE12: - | BF12: 996425 | BG12: 26-08-202/ | BH12: Mr. Shantanu Rooj | BI12: SG0014 | BJ12: 1665 | BL12: 396 | BM12: 0 | BN12: 0 | BO12: 0.2645685 | BP12: 26-08-2026 10:30:00 | BU12: 9 | BV12: BOM-CCU | CA12: 396 | CB12: TeamLease Edtech Limited | CC12: 29AAPCS2871R1Z7 | CE12: M | CF12: '11795656608260745 | CJ12: SG0014 | CK12: LST
A13: DW26/783895 | B13: 17-AUG-2026 | C13: 17-AUG-2026 | D13: Leadership | E13: Bengaluru | F13: MR. SHANTANU ROOJ | G13: SG0014 | H13: 3701618 | I13: 68-MUM-LED | K13: 26-08-2026 18:45:00 | L13: Kolkata-Mumbai | M13: Indigo | N13: 6E-5128 | O13: Economy | P13: BYCZRJ | Q13: 7920 | R13: 0 | S13: 967 | T13: 396 | U13: 9283 | V13: 0 | W13: MR. SHANTANU ROOJ | X13: Approved | Y13: 17-AUG-2026 | Z13: 15:11 | AA13: RFND | AB13: Teamlease Services Ltd | AC13: TLEdtech | AD13: 200117956567 | AE13: 1388000 | AF13: Founder and CEO | AG13: Round Trip | AH13: Domestic | AI13: LST | AJ13: shantanu@teamlease.com | AK13: Q | AL13: 800 | AM13: 0 | AN13: 44739307 | AO13: 17-AUG-2026 | AP13: 14:38 | AR13: CORPORATE | AS13: Official | AT13: Original | AY13: 9870333111 | AZ13: 29AAPCS2871R1Z7 | BA13: Karnataka | BB13: BYCZRJ | BC13: BYCZRJ | BD13: T004S | BE13: - | BF13: 996425 | BG13: 26-08-202/ | BH13: Mr. Shantanu Rooj | BI13: SG0014 | BJ13: 1665 | BL13: 396 | BM13: 0 | BN13: 0 | BO13: 0.2645685 | BP13: 26-08-2026 21:30:00 | BU13: 9 | BV13: CCU-BOM | CA13: 396 | CB13: TeamLease Edtech Limited | CC13: 29AAPCS2871R1Z7 | CE13: M | CF13: '11795656708261845 | CJ13: SG0014 | CK13: LST
A14: DW26/785429 | B14: 17-AUG-2026 | C14: 17-AUG-2026 | D14: Operations | E14: Bengaluru | F14: MR. ROSHAN DEEPAK PINTO | G14: T11294 | H14: 3701618 | I14: 67-MUM-ELO | K14: 26-08-2026 22:00:00 | L14: New Delhi-Bangalore | M14: Indigo | N14: 6E-0846 | O14: Economy | P14: JYRBGJ | Q14: 8280 | R14: 0 | S14: 382 | T14: 414 | U14: 9076 | V14: 75 | W14: MR. JAIDEEP KEWALRAMANI | X14: Approved | Y14: 17-AUG-2026 | Z14: 23:57 | AA14: FLOWN | AB14: Teamlease Services Ltd | AC14: TLEdtech | AD14: 200117967830 | AE14: 1388166 | AF14: Senior General Manager | AG14: Round Trip | AH14: Domestic | AI14: L9 | AJ14: roshan.pinto@teamlease.com | AK14: R | AL14: 800 | AM14: 0 | AN14: 44724877 | AO14: 17-AUG-2026 | AP14: 09:44 | AR14: CORPORATE | AS14: Official | AT14: Original | AY14: 9743374888 | AZ14: 29AAPCS2871R1Z7 | BA14: Karnataka | BB14: JYRBGJ | BC14: JYRBGJ | BD14: T004S | BE14: - | BF14: 996425 | BG14: 26-08-202/ | BH14: MR. Roshan Deepak Pinto | BI14: T11294 | BJ14: 1709 | BL14: 414 | BM14: 0 | BN14: 0 | BO14: 0.2715601 | BP14: 27-08-2026 00:55:00 | BU14: 9 | BV14: DEL-BLR | CA14: 414 | CB14: TeamLease Edtech Limited | CC14: 29AAPCS2871R1Z7 | CE14: M | CF14: '11796783008262200 | CJ14: T12553 | CK14: LST
A15: DW26/784868 | B15: 17-AUG-2026 | C15: 17-AUG-2026 | D15: Operations | E15: Bengaluru | F15: MR. ROSHAN DEEPAK PINTO | G15: T11294 | H15: 3701618 | I15: 67-MUM-ELO | K15: 24-08-2026 18:15:00 | L15: Bangalore-New Delhi | M15: Indigo | N15: 6E-6034 | O15: Economy | P15: H55U3Y | Q15: 8140 | R15: 0 | S15: 958 | T15: 407 | U15: 9505 | V15: 75 | W15: MR. JAIDEEP KEWALRAMANI | X15: Approved | Y15: 17-AUG-2026 | Z15: 23:57 | AA15: FLOWN | AB15: Teamlease Services Ltd | AC15: TLEdtech | AD15: 200117967829 | AE15: 1388166 | AF15: Senior General Manager | AG15: Round Trip | AH15: Domestic | AI15: L9 | AJ15: roshan.pinto@teamlease.com | AK15: Q | AL15: 800 | AM15: 0 | AN15: 44724877 | AO15: 17-AUG-2026 | AP15: 09:44 | AR15: CORPORATE | AS15: Official | AT15: Original | AY15: 9743374888 | AZ15: 29AAPCS2871R1Z7 | BA15: Karnataka | BB15: H55U3Y | BC15: H55U3Y | BD15: T004S | BE15: - | BF15: 996425 | BG15: 24-08-202/ | BH15: MR. Roshan Deepak Pinto | BI15: T11294 | BJ15: 1709 | BL15: 0 | BM15: 0 | BN15: 0 | BO15: 0.2715601 | BP15: 24-08-2026 21:05:00 | BU15: 7 | BV15: BLR-DEL | CA15: 407 | CB15: TeamLease Edtech Limited | CC15: 29AAPCS2871R1Z7 | CE15: M | CF15: '11796782908241815 | CJ15: T12553 | CK15: LST
A16: DW26/795993 | B16: 18-AUG-2026 | C16: 18-AUG-2026 | D16: University Bd | E16: Bengaluru | F16: MR. ASHUTOSH DUBEY | G16: T17010 | I16: 61-MUM-USE | K16: 24-08-2026 08:10:00 | L16: New Delhi-Guwahati | M16: AirIndia Express | N16: IX-1035 | O16: Economy | P16: R4C82C | Q16: 0 | R16: 6723 | S16: 1595 | T16: 0 | U16: 8318 | V16: 75 | W16: MR. MAHESH KUMAR | X16: Approved | Y16: 18-AUG-2026 | Z16: 10:15 | AA16: FLOWN | AB16: Teamlease Services Ltd | AC16: TLEdtech | AD16: 200117970188 | AE16: 6003228 | AF16: Senior Manager | AG16: One Way | AH16: Domestic | AI16: L7 | AJ16: ashutosh.dubey@teamlease.com | AK16: G | AL16: 549 | AM16: 0 | AN16: 44759631 | AO16: 18-AUG-2026 | AP16: 10:01 | AR16: CORPORATE | AS16: Official | AT16: Original | AY16: 8010118799 | AZ16: 29AAPCS2871R1Z7 | BA16: Karnataka | BB16: R4C82C | BC16: R4C82C | BD16: T004S | BE16: - | BF16: 996425 | BG16: 24-08-202/ | BH16: Mr. ASHUTOSH DUBEY | BI16: T17010 | BJ16: 1454 | BL16: 0 | BM16: 0 | BN16: 0 | BO16: 0.2310406 | BP16: 24-08-2026 10:40:00 | BU16: 6 | BV16: DEL-GAU | CA16: 0 | CB16: TeamLease Edtech Limited | CC16: 29AAPCS2871R1Z7 | CE16: M | CF16: '11797018808240810 | CJ16: T15604 | CK16: L8
A17: DA26/178427 | B17: 18-AUG-2026 | C17: 18-AUG-2026 | D17: Operations | E17: Bengaluru | F17: MR. AAYUSH LAL | G17: T16161 | I17: 69-MUM-PBP | K17: 21-08-2026 23:20:00 | L17: Chennai-New Delhi | M17: Air India | N17: AI-1845 | O17: Economy | P17: 5808869063 | Q17: 13300 | R17: 0 | S17: 787 | T17: 665 | U17: 14752 | V17: 75 | W17: MS. NIDHI RAJESH BAGLA | X17: Approved | Y17: 18-AUG-2026 | Z17: 10:43 | AA17: FLOWN | AB17: Teamlease Services Ltd | AC17: TLEdtech | AD17: 200117970808 | AE17: 3937212 | AF17: Senior Project Manager | AG17: Round Trip | AH17: Domestic | AI17: L7 | AJ17: aayush.lal@teamlease.com | AK17: K | AL17: 749 | AM17: 170 | AN17: 44725527 | AO17: 18-AUG-2026 | AP17: 10:31 | AR17: CORPORATE | AS17: Official | AT17: Original | AY17: 7076663907 | AZ17: 29AAPCS2871R1Z7 | BA17: Karnataka | BB17: '0985808869063 | BC17: E8LTZ6 | BD17: T004S | BE17: - | BF17: 996425 | BG17: 21-08-202/ | BH17: Mr. AAYUSH LAL | BI17: T16161 | BJ17: 1760 | BL17: 0 | BM17: 0 | BN17: 0 | BO17: 0.279664 | BP17: 22-08-2026 02:15:00 | BU17: 3 | BV17: MAA-DEL | CA17: 665 | CB17: TeamLease Edtech Limited | CC17: 29AAPCS2871R1Z7 | CE17: M | CF17: '11797080808212320 | CJ17: T17642 | CK17: L8
A18: DW26/796548 | B18: 18-AUG-2026 | C18: 18-AUG-2026 | D18: Operations | E18: Bengaluru | F18: MR. AAYUSH LAL | G18: T16161 | I18: 69-MUM-PBP | K18: 19-08-2026 14:30:00 | L18: New Delhi-Chennai | M18: SpiceJet | N18: SG-9300 | O18: Economy | P18: FFKVQD | Q18: 7760 | R18: 0 | S18: 378 | T18: 388 | U18: 8526 | V18: 75 | W18: MS. NIDHI RAJESH BAGLA | X18: Approved | Y18: 18-AUG-2026 | Z18: 10:43 | AA18: RFND | AB18: Teamlease Services Ltd | AC18: TLEdtech | AD18: 200117970807 | AE18: 3937212 | AF18: Senior Project Manager | AG18: Round Trip | AH18: Domestic | AI18: L7 | AJ18: aayush.lal@teamlease.com | AK18: W | AL18: 699 | AM18: 0 | AN18: 44725527 | AO18: 18-AUG-2026 | AP18: 10:31 | AR18: CORPORATE | AS18: Official | AT18: Original | AY18: 7076663907 | AZ18: 29AAPCS2871R1Z7 | BA18: Karnataka | BB18: FFKVQD | BC18: FFKVQD | BD18: T004S | BE18: - | BF18: 996425 | BG18: 19-08-202/ | BH18: Mr. AAYUSH LAL | BI18: T16161 | BJ18: 1760 | BL18: 388 | BM18: 0 | BN18: 0 | BO18: 0.279664 | BP18: 19-08-2026 17:30:00 | BU18: 1 | BV18: DEL-MAA | CA18: 388 | CB18: TeamLease Edtech Limited | CC18: 29AAPCS2871R1Z7 | CE18: M | CF18: '11797080708191430 | CJ18: T17642 | CK18: L8
A19: DW26/791733 | B19: 18-AUG-2026 | C19: 18-AUG-2026 | D19: Operations | E19: Bengaluru | F19: MR. AAYUSH LAL | G19: T16161 | I19: 69-MUM-PBP | K19: 25-08-2026 09:10:00 | L19: New Delhi-Gaya | M19: Indigo | N19: 6E-2448 | O19: Economy | P19: CDD3JA | Q19: 6100 | R19: 0 | S19: 381 | T19: 305 | U19: 6786 | V19: 75 | W19: MS. NIDHI RAJESH BAGLA | X19: Approved | Y19: 18-AUG-2026 | Z19: 16:34 | AA19: FLOWN | AB19: Teamlease Services Ltd | AC19: TLEdtech | AD19: 200117979769 | AE19: 3937212 | AF19: Senior Project Manager | AG19: One Way | AH19: Domestic | AI19: L7 | AJ19: aayush.lal@teamlease.com | AK19: O | AL19: 400 | AM19: 0 | AN19: 44773152 | AO19: 18-AUG-2026 | AP19: 15:36 | AR19: CORPORATE | AS19: Scheduled Visit | AT19: Original | AY19: 7076663907 | AZ19: 29AAPCS2871R1Z7 | BA19: Karnataka | BB19: CDD3JA | BC19: CDD3JA | BD19: T004S | BE19: - | BF19: 996425 | BG19: 25-08-202/ | BH19: Mr. AAYUSH LAL | BI19: T16161 | BJ19: 886 | BL19: 305 | BM19: 0 | BN19: 0 | BO19: 0.1407854 | BP19: 25-08-2026 11:00:00 | BU19: 7 | BV19: DEL-GAY | CA19: 305 | CB19: TeamLease Edtech Limited | CC19: 29AAPCS2871R1Z7 | CE19: M | CF19: '11797976908250910 | CJ19: T17642 | CK19: L8
A20: DW26/791750 | B20: 18-AUG-2026 | C20: 18-AUG-2026 | D20: Operations | E20: Bengaluru | F20: MR. AAYUSH LAL | G20: T16161 | I20: 69-MUM-PBP | K20: 30-08-2026 20:35:00 | L20: Ranchi-New Delhi | M20: Indigo | N20: 6E-6274 | O20: Economy | P20: CEUFVK | Q20: 6200 | R20: 0 | S20: 1233 | T20: 310 | U20: 7743 | V20: 75 | W20: MS. NIDHI RAJESH BAGLA | X20: Approved | Y20: 18-AUG-2026 | Z20: 16:37 | AA20: FLOWN | AB20: Teamlease Services Ltd | AC20: TLEdtech | AD20: 200117979829 | AE20: 3937212 | AF20: Senior Project Manager | AG20: One Way | AH20: Domestic | AI20: L7 | AJ20: aayush.lal@teamlease.com | AK20: R | AL20: 600 | AM20: 0 | AN20: 44775874 | AO20: 18-AUG-2026 | AP20: 16:34 | AR20: CORPORATE | AS20: Scheduled Visit | AT20: Original | AY20: 7076663907 | AZ20: 29AAPCS2871R1Z7 | BA20: Karnataka | BB20: CEUFVK | BC20: CEUFVK | BD20: T004S | BE20: - | BF20: 996425 | BG20: 30-08-202/ | BH20: Mr. AAYUSH LAL | BI20: T16161 | BJ20: 1007 | BL20: 310 | BM20: 0 | BN20: 0 | BO20: 0.1600123 | BP20: 30-08-2026 22:35:00 | BU20: 12 | BV20: IXR-DEL | CA20: 310 | CB20: TeamLease Edtech Limited | CC20: 29AAPCS2871R1Z7 | CE20: M | CF20: '11797982908302035 | CJ20: T17642 | CK20: L8
A21: DW26/798332 | B21: 19-AUG-2026 | C21: 19-AUG-2026 | D21: Operations | E21: Bengaluru | F21: MR. AAYUSH LAL | G21: T16161 | I21: 69-MUM-PBP | K21: 19-08-2026 11:00:00 | L21: New Delhi-Chennai | M21: Indigo | N21: 6E-0434 | O21: Economy | P21: BYS3SW | Q21: 9240 | R21: 0 | S21: 397 | T21: 462 | U21: 10099 | V21: 75 | W21: MS. NIDHI RAJESH BAGLA | X21: Approved | Y21: 19-AUG-2026 | Z21: 07:33 | AA21: FLOWN | AB21: Teamlease Services Ltd | AC21: TLEdtech | AD21: 200117988871 | AE21: 3937212 | AF21: Senior Project Manager | AG21: One Way | AH21: Domestic | AI21: L7 | AJ21: aayush.lal@teamlease.com | AK21: R | AL21: 800 | AM21: 0 | AN21: 44787679 | AO21: 19-AUG-2026 | AP21: 07:27 | AR21: CORPORATE | AS21: Official | AT21: Original | AY21: 7076663907 | AZ21: 29AAPCS2871R1Z7 | BA21: Karnataka | BB21: BYS3SW | BC21: BYS3SW | BD21: T004S | BE21: - | BF21: 996425 | BG21: 19-08-202/ | BH21: Mr. AAYUSH LAL | BI21: T16161 | BJ21: 1760 | BL21: 462 | BM21: 0 | BN21: 0 | BO21: 0.279664 | BP21: 19-08-2026 13:50:00 | BU21: 0 | BV21: DEL-MAA | CA21: 462 | CB21: TeamLease Edtech Limited | CC21: 29AAPCS2871R1Z7 | CE21: M | CF21: '11798887108191100 | CJ21: T17642 | CK21: L8
A22: DA26/181264 | B22: 19-AUG-2026 | C22: 19-AUG-2026 | D22: University B2C | E22: Bengaluru | F22: MR. UDITENDU BOSE | G22: SG0320 | H22: 3701618 | I22: 62-MUM-SSS | K22: 24-08-2026 10:30:00 | L22: Kolkata-Mumbai | M22: Air India | N22: AI-2772 | O22: Economy | P22: 5808907262 | Q22: 7840 | R22: 0 | S22: 967 | T22: 392 | U22: 9199 | V22: 75 | W22: MR. SHANTANU ROOJ | X22: Approved | Y22: 19-AUG-2026 | Z22: 16:09 | AA22: RFND | AB22: Teamlease Services Ltd | AC22: TLEdtech | AD22: 200117997990 | AE22: 1388087 | AF22: Vice President - Consumer Sales | AG22: Round Trip | AH22: Domestic | AI22: L10 | AJ22: uditendu.bose@teamlease.com | AK22: T | AL22: 749 | AM22: 170 | AN22: 44798324 | AO22: 19-AUG-2026 | AP22: 13:59 | AR22: CORPORATE | AS22: Official | AT22: Original | AY22: 9971252225 | AZ22: 29AAPCS2871R1Z7 | BA22: Karnataka | BB22: '0985808907262 | BC22: ETRM8B | BD22: T004S | BE22: - | BF22: 996425 | BG22: 24-08-202/ | BH22: Ms. Priyanka Thakur | BI22: T16868 | BJ22: 1665 | BL22: 0 | BM22: 0 | BN22: 0 | BO22: 0.2645685 | BP22: 24-08-2026 13:35:00 | BU22: 5 | BV22: CCU-BOM | CA22: 392 | CB22: TeamLease Edtech Limited | CC22: 29AAPCS2871R1Z7 | CE22: M | CF22: '11799799008241030 | CJ22: SG0014 | CK22: LST
A23: DA26/181266 | B23: 19-AUG-2026 | C23: 19-AUG-2026 | D23: University B2C | E23: Bengaluru | F23: MR. UDITENDU BOSE | G23: SG0320 | H23: 3701618 | I23: 62-MUM-SSS | K23: 27-08-2026 06:55:00 | L23: Mumbai-Kolkata | M23: Air India | N23: AI-2771 | O23: Economy | P23: 5808907264 | Q23: 7840 | R23: 0 | S23: 439 | T23: 392 | U23: 8671 | V23: 75 | W23: MR. SHANTANU ROOJ | X23: Approved | Y23: 19-AUG-2026 | Z23: 16:09 | AA23: FLOWN | AB23: Teamlease Services Ltd | AC23: TLEdtech | AD23: 200117997991 | AE23: 1388087 | AF23: Vice President - Consumer Sales | AG23: Round Trip | AH23: Domestic | AI23: L10 | AJ23: uditendu.bose@teamlease.com | AK23: T | AL23: 749 | AM23: 170 | AN23: 44798324 | AO23: 19-AUG-2026 | AP23: 13:59 | AR23: CORPORATE | AS23: Official | AT23: Original | AY23: 9971252225 | AZ23: 29AAPCS2871R1Z7 | BA23: Karnataka | BB23: '0985808907264 | BC23: ETQQ6X | BD23: T004S | BE23: - | BF23: 996425 | BG23: 27-08-202/ | BH23: Ms. Priyanka Thakur | BI23: T16868 | BJ23: 1665 | BL23: 0 | BM23: 0 | BN23: 0 | BO23: 0.2645685 | BP23: 27-08-2026 09:45:00 | BU23: 8 | BV23: BOM-CCU | CA23: 392 | CB23: TeamLease Edtech Limited | CC23: 29AAPCS2871R1Z7 | CE23: M | CF23: '11799799108270655 | CJ23: SG0014 | CK23: LST
A24: DW26/799416 | B24: 19-AUG-2026 | C24: 19-AUG-2026 | D24: University B2C | E24: Bengaluru | F24: MR. UDITENDU BOSE | G24: SG0320 | H24: 3701618 | I24: 62-MUM-SSS | K24: 23-08-2026 11:35:00 | L24: Kolkata-Mumbai | M24: Indigo | N24: 6E-5288 | O24: Economy | P24: KDJR9N | Q24: 8220 | R24: 0 | S24: 978 | T24: 411 | U24: 9609 | V24: 75 | W24: MR. SHANTANU ROOJ | X24: Approved | Y24: 19-AUG-2026 | Z24: 17:05 | AA24: FLOWN | AB24: Teamlease Services Ltd | AC24: TLEdtech | AD24: 200117999595 | AE24: 1388087 | AF24: Vice President - Consumer Sales | AG24: One Way | AH24: Domestic | AI24: L10 | AJ24: uditendu.bose@teamlease.com | AK24: R | AL24: 800 | AM24: 0 | AN24: 44806175 | AO24: 19-AUG-2026 | AP24: 16:55 | AR24: CORPORATE | AS24: Official | AT24: Original | AY24: 9971252225 | AZ24: 29AAPCS2871R1Z7 | BA24: Karnataka | BB24: KDJR9N | BC24: KDJR9N | BD24: T004S | BE24: - | BF24: 996425 | BG24: 23-08-202/ | BH24: Ms. Priyanka Thakur | BI24: T16868 | BJ24: 1665 | BL24: 411 | BM24: 0 | BN24: 0 | BO24: 0.2645685 | BP24: 23-08-2026 14:35:00 | BU24: 4 | BV24: CCU-BOM | CA24: 411 | CB24: TeamLease Edtech Limited | CC24: 29AAPCS2871R1Z7 | CE24: M | CF24: '11799959508231135 | CJ24: SG0014 | CK24: LST
A25: DW26/799382 | B25: 19-AUG-2026 | C25: 19-AUG-2026 | D25: Leadership | E25: Bengaluru | F25: MR. SHANTANU ROOJ | G25: SG0014 | H25: 3701618 | I25: 68-MUM-LED | K25: 21-08-2026 20:45:00 | L25: New Delhi-Mumbai | M25: Indigo | N25: 6E-0853 | O25: Economy | P25: K9PBJM | Q25: 7560 | R25: 0 | S25: 485 | T25: 378 | U25: 8423 | V25: 0 | W25: MR. SHANTANU ROOJ | X25: Approved | Y25: 19-AUG-2026 | Z25: 18:37 | AA25: RFND | AB25: Teamlease Services Ltd | AC25: TLEdtech | AD25: 200118001834 | AE25: 1388000 | AF25: Founder and CEO | AG25: Round Trip | AH25: Domestic | AI25: LST | AJ25: shantanu@teamlease.com | AK25: O | AL25: 600 | AM25: 0 | AN25: 44809720 | AO25: 19-AUG-2026 | AP25: 18:30 | AR25: CORPORATE | AS25: Official | AT25: Original | AY25: 9870333111 | AZ25: 29AAPCS2871R1Z7 | BA25: Karnataka | BB25: K9PBJM | BC25: K9PBJM | BD25: T004S | BE25: - | BF25: 996425 | BG25: 21-08-202/ | BH25: Mr. Shantanu Rooj | BI25: SG0014 | BJ25: 1139 | BL25: 378 | BM25: 0 | BN25: 0 | BO25: 0.1809871 | BP25: 21-08-2026 23:00:00 | BU25: 2 | BV25: DEL-BOM | CA25: 378 | CB25: TeamLease Edtech Limited | CC25: 29AAPCS2871R1Z7 | CE25: M | CF25: '11800183408212045 | CJ25: SG0014 | CK25: LST
A26: DA26/181589 | B26: 19-AUG-2026 | C26: 19-AUG-2026 | D26: Leadership | E26: Bengaluru | F26: MR. SHANTANU ROOJ | G26: SG0014 | H26: 3701618 | I26: 68-MUM-LED | K26: 21-08-2026 08:30:00 | L26: Mumbai-New Delhi | M26: Air India | N26: AI-2970 | O26: Economy | P26: 5808911595 | Q26: 6480 | R26: 0 | S26: 505 | T26: 324 | U26: 7309 | V26: 0 | W26: MR. SHANTANU ROOJ | X26: Approved | Y26: 19-AUG-2026 | Z26: 18:37 | AA26: FLOWN | AB26: Teamlease Services Ltd | AC26: TLEdtech | AD26: 200118001833 | AE26: 1388000 | AF26: Founder and CEO | AG26: Round Trip | AH26: Domestic | AI26: LST | AJ26: shantanu@teamlease.com | AK26: T | AL26: 549 | AM26: 170 | AN26: 44809720 | AO26: 19-AUG-2026 | AP26: 18:30 | AR26: CORPORATE | AS26: Official | AT26: Original | AY26: 9870333111 | AZ26: 29AAPCS2871R1Z7 | BA26: Karnataka | BB26: '0985808911595 | BC26: EVL5VE | BD26: T004S | BE26: - | BF26: 996425 | BG26: 21-08-202/ | BH26: Mr. Shantanu Rooj | BI26: SG0014 | BJ26: 1139 | BL26: 0 | BM26: 0 | BN26: 0 | BO26: 0.1809871 | BP26: 21-08-2026 10:50:00 | BU26: 2 | BV26: BOM-DEL | CA26: 324 | CB26: TeamLease Edtech Limited | CC26: 29AAPCS2871R1Z7 | CE26: M | CF26: '11800183308210830 | CJ26: SG0014 | CK26: LST
A27: DA26/182479 | B27: 20-AUG-2026 | C27: 20-AUG-2026 | D27: Leadership | E27: Bengaluru | F27: MR. SHANTANU ROOJ | G27: SG0014 | H27: 3701618 | I27: 68-MUM-LED | K27: 21-08-2026 21:30:00 | L27: New Delhi-Mumbai | M27: Air India | N27: AI-2433 | O27: Economy | P27: 5808926793 | Q27: 7620 | R27: 0 | S27: 477 | T27: 381 | U27: 8478 | V27: 0 | W27: MR. SHANTANU ROOJ | X27: Approved | Y27: 20-AUG-2026 | Z27: 13:24 | AA27: FLOWN | AB27: Teamlease Services Ltd | AC27: TLEdtech | AD27: 200118013519 | AE27: 1388000 | AF27: Founder and CEO | AG27: One Way | AH27: Domestic | AI27: LST | AJ27: shantanu@teamlease.com | AK27: G | AL27: 549 | AM27: 170 | AN27: 44824925 | AO27: 20-AUG-2026 | AP27: 13:19 | AR27: CORPORATE | AS27: Official | AT27: Original | AY27: 9870333111 | AZ27: 29AAPCS2871R1Z7 | BA27: Karnataka | BB27: '0985808926793 | BC27: FB4UCA | BD27: T004S | BE27: - | BF27: 996425 | BG27: 21-08-202/ | BH27: Mr. Shantanu Rooj | BI27: SG0014 | BJ27: 1139 | BL27: 0 | BM27: 0 | BN27: 0 | BO27: 0.1809871 | BP27: 21-08-2026 23:55:00 | BU27: 1 | BV27: DEL-BOM | CA27: 381 | CB27: TeamLease Edtech Limited | CC27: 29AAPCS2871R1Z7 | CE27: M | CF27: '11801351908212130 | CJ27: SG0014 | CK27: LST
A28: DW26/806555 | B28: 20-AUG-2026 | C28: 20-AUG-2026 | D28: Leadership | E28: Bengaluru | F28: MR. SHANTANU ROOJ | G28: SG0014 | H28: 3701618 | I28: 68-MUM-LED | K28: 28-08-2026 19:35:00 | L28: Ahmedabad-Mumbai | M28: Indigo | N28: 6E-5160 | O28: Economy | P28: R8PE7P | Q28: 8620 | R28: 0 | S28: 1030 | T28: 431 | U28: 10081 | V28: 0 | W28: MR. SHANTANU ROOJ | X28: Approved | Y28: 20-AUG-2026 | Z28: 15:11 | AA28: FLOWN | AB28: Teamlease Services Ltd | AC28: TLEdtech | AD28: 200118015907 | AE28: 1388000 | AF28: Founder and CEO | AG28: Round Trip | AH28: Domestic | AI28: LST | AJ28: shantanu@teamlease.com | AK28: V | AL28: 275 | AM28: 0 | AN28: 44828403 | AO28: 20-AUG-2026 | AP28: 14:53 | AR28: CORPORATE | AS28: Official | AT28: Original | AY28: 9870333111 | AZ28: 29AAPCS2871R1Z7 | BA28: Karnataka | BB28: R8PE7P | BC28: R8PE7P | BD28: T004S | BE28: - | BF28: 996425 | BG28: 28-08-202/ | BH28: Mr. Shantanu Rooj | BI28: SG0014 | BJ28: 442 | BL28: 431 | BM28: 0 | BN28: 0 | BO28: 0.0702338 | BP28: 28-08-2026 21:05:00 | BU28: 8 | BV28: AMD-BOM | CA28: 431 | CB28: TeamLease Edtech Limited | CC28: 29AAPCS2871R1Z7 | CE28: M | CF28: '11801590708281935 | CJ28: SG0014 | CK28: LST
A29: DA26/182688 | B29: 20-AUG-2026 | C29: 20-AUG-2026 | D29: Leadership | E29: Bengaluru | F29: MR. SHANTANU ROOJ | G29: SG0014 | H29: 3701618 | I29: 68-MUM-LED | K29: 28-08-2026 10:20:00 | L29: Mumbai-Ahmedabad | M29: Air India | N29: AI-2847 | O29: Economy | P29: 5808929510 | Q29: 6940 | R29: 0 | S29: 424 | T29: 347 | U29: 7711 | V29: 0 | W29: MR. SHANTANU ROOJ | X29: Approved | Y29: 20-AUG-2026 | Z29: 15:11 | AA29: FLOWN | AB29: Teamlease Services Ltd | AC29: TLEdtech | AD29: 200118015906 | AE29: 1388000 | AF29: Founder and CEO | AG29: Round Trip | AH29: Domestic | AI29: LST | AJ29: shantanu@teamlease.com | AK29: Q | AL29: 299 | AM29: 170 | AN29: 44828403 | AO29: 20-AUG-2026 | AP29: 14:53 | AR29: CORPORATE | AS29: Official | AT29: Original | AY29: 9870333111 | AZ29: 29AAPCS2871R1Z7 | BA29: Karnataka | BB29: '0985808929510 | BC29: FCBVSC | BD29: T004S | BE29: - | BF29: 996425 | BG29: 28-08-202/ | BH29: Mr. Shantanu Rooj | BI29: SG0014 | BJ29: 442 | BL29: 0 | BM29: 0 | BN29: 0 | BO29: 0.0702338 | BP29: 28-08-2026 11:50:00 | BU29: 8 | BV29: BOM-AMD | CA29: 347 | CB29: TeamLease Edtech Limited | CC29: 29AAPCS2871R1Z7 | CE29: M | CF29: '11801590608281020 | CJ29: SG0014 | CK29: LST
A30: DW26/808707 | B30: 20-AUG-2026 | C30: 20-AUG-2026 | D30: Premier B2C | E30: Bengaluru | F30: MS. SHRUTIKA SHARMA | G30: T16151 | I30: 69-MUM-PBD | K30: 03-09-2026 17:45:00 | L30: Bangalore-Mumbai | M30: Akasa Air | N30: QP-1986 | O30: Economy | P30: YYS1MT | Q30: 6160 | R30: 0 | S30: 991 | T30: 308 | U30: 7459 | V30: 75 | W30: MS. GEETIKA KOHLI | X30: Approved | Y30: 20-AUG-2026 | Z30: 16:47 | AB30: Teamlease Services Ltd | AC30: TLEdtech | AD30: 200118018169 | AE30: 3906980 | AF30: Assistant General Manager | AG30: Round Trip | AH30: Domestic | AI30: L8 | AJ30: shrutika.sharma@teamlease.com | AK30: R2 | AL30: 0 | AM30: 0 | AN30: 44829110 | AO30: 20-AUG-2026 | AP30: 15:12 | AR30: CORPORATE | AS30: Official | AT30: Original | AY30: 9930515039 | AZ30: 29AAPCS2871R1Z7 | BA30: Karnataka | BB30: YYS1MT | BC30: YYS1MT | BD30: T004S | BE30: - | BF30: 996425 | BG30: 03-09-202/ | BH30: Mr. Satyavan Sawant | BI30: T17247 | BJ30: 835 | BL30: 0 | BM30: 154 | BN30: 154 | BO30: 0.1326815 | BP30: 03-09-2026 19:40:00 | BU30: 14 | BV30: BLR-BOM | CA30: 308 | CB30: TeamLease Edtech Limited | CC30: 29AAPCS2871R1Z7 | CE30: F | CF30: '11801816909031745 | CJ30: SG0400 | CK30: L10
A31: DW26/806969 | B31: 20-AUG-2026 | C31: 20-AUG-2026 | D31: Premier B2C | E31: Bengaluru | F31: MS. SHRUTIKA SHARMA | G31: T16151 | I31: 69-MUM-PBD | K31: 31-08-2026 08:05:00 | L31: Mumbai-Bangalore | M31: Indigo | N31: 6E-5193 | O31: Economy | P31: TH3MFH | Q31: 7520 | R31: 0 | S31: 437 | T31: 376 | U31: 8333 | V31: 75 | W31: MS. GEETIKA KOHLI | X31: Approved | Y31: 20-AUG-2026 | Z31: 16:47 | AA31: FLOWN | AB31: Teamlease Services Ltd | AC31: TLEdtech | AD31: 200118018168 | AE31: 3906980 | AF31: Assistant General Manager | AG31: Round Trip | AH31: Domestic | AI31: L8 | AJ31: shrutika.sharma@teamlease.com | AK31: P | AL31: 400 | AM31: 0 | AN31: 44829110 | AO31: 20-AUG-2026 | AP31: 15:12 | AR31: CORPORATE | AS31: Official | AT31: Original | AY31: 9930515039 | AZ31: 29AAPCS2871R1Z7 | BA31: Karnataka | BB31: TH3MFH | BC31: TH3MFH | BD31: T004S | BE31: - | BF31: 996425 | BG31: 31-08-202/ | BH31: Mr. Satyavan Sawant | BI31: T17247 | BJ31: 835 | BL31: 376 | BM31: 0 | BN31: 0 | BO31: 0.1326815 | BP31: 31-08-2026 09:55:00 | BU31: 11 | BV31: BOM-BLR | CA31: 376 | CB31: TeamLease Edtech Limited | CC31: 29AAPCS2871R1Z7 | CE31: F | CF31: '11801816808310805 | CJ31: SG0400 | CK31: L10
A32: DW26/807439 | B32: 20-AUG-2026 | C32: 20-AUG-2026 | D32: Operations | E32: Bengaluru | F32: MR. DINESH KUMAR | G32: T11310 | H32: 3701618 | I32: 63-DEL-DAS | K32: 27-08-2026 21:20:00 | L32: Aurangabad-New Delhi | M32: Indigo | N32: 6E-6257 | O32: Economy | P32: WG7C4X | Q32: 6660 | R32: 0 | S32: 1120 | T32: 333 | U32: 8113 | V32: 75 | W32: MR. NIPUN SHARMA | X32: Approved | Y32: 20-AUG-2026 | Z32: 19:08 | AA32: FLOWN | AB32: Teamlease Services Ltd | AC32: TL Digital | AD32: 200118021115 | AE32: 1388459 | AF32: Head - Operations (Enterprise Services) | AG32: Round Trip | AH32: Domestic | AI32: L9 | AJ32: dinesh.gupta@teamlease.com | AK32: R | AL32: 400 | AM32: 0 | AN32: 44833854 | AO32: 20-AUG-2026 | AP32: 18:21 | AR32: CORPORATE | AS32: Official | AT32: Original | AY32: 8826526715 | AZ32: 29AAPCS2871R1Z7 | BA32: Karnataka | BB32: WG7C4X | BC32: WG7C4X | BD32: T004S | BE32: - | BF32: 996425 | BG32: 27-08-202/ | BH32: Mr. DINESH KUMAR | BI32: T11310 | BJ32: 983 | BL32: 333 | BM32: 0 | BN32: 0 | BO32: 0.1561987 | BP32: 27-08-2026 23:25:00 | BU32: 7 | BV32: IXU-DEL | CA32: 333 | CB32: TeamLease Edtech Limited | CC32: 29AAPCS2871R1Z7 | CE32: M | CF32: '11802111508272120 | CJ32: T16237 | CK32: LST
A33: DW26/807631 | B33: 20-AUG-2026 | C33: 20-AUG-2026 | D33: Operations | E33: Bengaluru | F33: MR. DINESH KUMAR | G33: T11310 | H33: 3701618 | I33: 63-DEL-DAS | K33: 23-08-2026 19:10:00 | L33: New Delhi-Aurangabad | M33: Indigo | N33: 6E-6256 | O33: Economy | P33: XHHZ8U | Q33: 7280 | R33: 0 | S33: 392 | T33: 364 | U33: 8036 | V33: 75 | W33: MR. NIPUN SHARMA | X33: Approved | Y33: 20-AUG-2026 | Z33: 19:08 | AA33: FLOWN | AB33: Teamlease Services Ltd | AC33: TL Digital | AD33: 200118021114 | AE33: 1388459 | AF33: Head - Operations (Enterprise Services) | AG33: Round Trip | AH33: Domestic | AI33: L9 | AJ33: dinesh.gupta@teamlease.com | AK33: P | AL33: 400 | AM33: 0 | AN33: 44833854 | AO33: 20-AUG-2026 | AP33: 18:21 | AR33: CORPORATE | AS33: Official | AT33: Original | AY33: 8826526715 | AZ33: 29AAPCS2871R1Z7 | BA33: Karnataka | BB33: XHHZ8U | BC33: XHHZ8U | BD33: T004S | BE33: - | BF33: 996425 | BG33: 23-08-202/ | BH33: Mr. DINESH KUMAR | BI33: T11310 | BJ33: 983 | BL33: 364 | BM33: 0 | BN33: 0 | BO33: 0.1561987 | BP33: 23-08-2026 20:50:00 | BU33: 3 | BV33: DEL-IXU | CA33: 364 | CB33: TeamLease Edtech Limited | CC33: 29AAPCS2871R1Z7 | CE33: M | CF33: '11802111408231910 | CJ33: T16237 | CK33: LST
A34: DW26/818659 | B34: 22-AUG-2026 | C34: 22-AUG-2026 | D34: Operations | E34: Bengaluru | F34: MRS. SRIMATHI R | G34: SG0444 | H34: 3701618 | I34: 61-MUM-ASO | K34: 31-08-2026 13:30:00 | L34: Mumbai-Gwalior | M34: Indigo | N34: 6E-5276 | O34: Economy | P34: XHSK3E | Q34: 6000 | R34: 0 | S34: 443 | T34: 300 | U34: 6743 | V34: 75 | W34: MR. JAIDEEP KEWALRAMANI | X34: Approved | Y34: 22-AUG-2026 | Z34: 03:59 | AA34: FLOWN | AB34: Teamlease Services Ltd | AC34: TLEdtech | AD34: 200118040752 | AE34: 1388479 | AF34: Head - University Operations | AG34: Round Trip | AH34: Domestic | AI34: L10 | AJ34: srimathi.krishnan@teamlease.com | AK34: O | AL34: 400 | AM34: 0 | AN34: 44856343 | AO34: 21-AUG-2026 | AP34: 16:31 | AR34: CORPORATE | AS34: Official | AT34: Original | AY34: 8903128200 | AZ34: 29AAPCS2871R1Z7 | BA34: Karnataka | BB34: XHSK3E | BC34: XHSK3E | BD34: T004S | BE34: - | BF34: 996425 | BG34: 31-08-202/ | BH34: Mrs. SRIMATHI R | BI34: SG0444 | BJ34: 972 | BL34: 300 | BM34: 0 | BN34: 0 | BO34: 0.1544508 | BP34: 31-08-2026 15:40:00 | BU34: 10 | BV34: BOM-GWL | CA34: 300 | CB34: TeamLease Edtech Limited | CC34: 29AAPCS2871R1Z7 | CE34: F | CF34: '11804075208311330 | CJ34: T12553 | CK34: LST
A35: DW26/817320 | B35: 22-AUG-2026 | C35: 22-AUG-2026 | D35: Operations | E35: Bengaluru | F35: MRS. SRIMATHI R | G35: SG0444 | H35: 3701618 | I35: 61-MUM-ASO | K35: 02-09-2026 16:15:00 | L35: Gwalior-Mumbai | M35: Indigo | N35: 6E-5265 | O35: Economy | P35: IE8PPA | Q35: 6780 | R35: 0 | S35: 1136 | T35: 339 | U35: 8255 | V35: 75 | W35: MR. JAIDEEP KEWALRAMANI | X35: Approved | Y35: 22-AUG-2026 | Z35: 03:59 | AA35: RFND | AB35: Teamlease Services Ltd | AC35: TLEdtech | AD35: 200118040753 | AE35: 1388479 | AF35: Head - University Operations | AG35: Round Trip | AH35: Domestic | AI35: L10 | AJ35: srimathi.krishnan@teamlease.com | AK35: V | AL35: 400 | AM35: 0 | AN35: 44856343 | AO35: 21-AUG-2026 | AP35: 16:31 | AR35: CORPORATE | AS35: Official | AT35: Original | AY35: 8903128200 | AZ35: 29AAPCS2871R1Z7 | BA35: Karnataka | BB35: IE8PPA | BC35: IE8PPA | BD35: T004S | BE35: - | BF35: 996425 | BG35: 02-09-202/ | BH35: Mrs. SRIMATHI R | BI35: SG0444 | BJ35: 972 | BL35: 339 | BM35: 0 | BN35: 0 | BO35: 0.1544508 | BP35: 02-09-2026 18:10:00 | BU35: 12 | BV35: GWL-BOM | CA35: 339 | CB35: TeamLease Edtech Limited | CC35: 29AAPCS2871R1Z7 | CE35: F | CF35: '11804075309021615 | CJ35: T12553 | CK35: LST
A36: DW26/817440 | B36: 22-AUG-2026 | C36: 22-AUG-2026 | D36: Operations | E36: Bengaluru | F36: MR. PRATHAMESH JADHAV | G36: T16692 | I36: 62-MUM-PBO | K36: 27-08-2026 16:40:00 | L36: Chennai-Mumbai | M36: Indigo | N36: 6E-5104 | O36: Economy | P36: K6M28F | Q36: 7800 | R36: 0 | S36: 805 | T36: 390 | U36: 8995 | V36: 75 | W36: MS. NIDHI RAJESH BAGLA | X36: Approved | Y36: 22-AUG-2026 | Z36: 11:02 | AA36: RFND | AB36: Teamlease Services Ltd | AC36: TLEdtech | AD36: 200118042397 | AE36: 5246483 | AF36: Manager | AG36: Round Trip | AH36: Domestic | AI36: L6 | AJ36: prathamesh.jadhav@teamlease.com | AK36: P | AL36: 600 | AM36: 0 | AN36: 44855536 | AO36: 21-AUG-2026 | AP36: 16:04 | AR36: CORPORATE | AS36: Official | AT36: Original | AY36: 9867718072 | AZ36: 29AAPCS2871R1Z7 | BA36: Karnataka | BB36: K6M28F | BC36: K6M28F | BD36: T004S | BE36: - | BF36: 996425 | BG36: 27-08-202/ | BH36: Mr. Prathamesh JADHAV | BI36: T16692 | BJ36: 1034 | BL36: 390 | BM36: 0 | BN36: 0 | BO36: 0.1643026 | BP36: 27-08-2026 18:40:00 | BU36: 6 | BV36: MAA-BOM | CA36: 390 | CB36: TeamLease Edtech Limited | CC36: 29AAPCS2871R1Z7 | CE36: M | CF36: '11804239708271640 | CJ36: T17642 | CK36: L8
A37: DW26/818413 | B37: 22-AUG-2026 | C37: 22-AUG-2026 | D37: Operations | E37: Bengaluru | F37: MR. PRATHAMESH JADHAV | G37: T16692 | I37: 62-MUM-PBO | K37: 23-08-2026 17:25:00 | L37: Mumbai-Chennai | M37: Indigo | N37: 6E-5048 | O37: Economy | P37: V5S74Y | Q37: 8260 | R37: 0 | S37: 436 | T37: 413 | U37: 9109 | V37: 75 | W37: MS. NIDHI RAJESH BAGLA | X37: Approved | Y37: 22-AUG-2026 | Z37: 11:02 | AA37: RFND | AB37: Teamlease Services Ltd | AC37: TLEdtech | AD37: 200118042396 | AE37: 5246483 | AF37: Manager | AG37: Round Trip | AH37: Domestic | AI37: L6 | AJ37: prathamesh.jadhav@teamlease.com | AK37: J | AL37: 600 | AM37: 0 | AN37: 44855536 | AO37: 21-AUG-2026 | AP37: 16:04 | AR37: CORPORATE | AS37: Official | AT37: Original | AY37: 9867718072 | AZ37: 29AAPCS2871R1Z7 | BA37: Karnataka | BB37: V5S74Y | BC37: V5S74Y | BD37: T004S | BE37: - | BF37: 996425 | BG37: 23-08-202/ | BH37: Mr. Prathamesh JADHAV | BI37: T16692 | BJ37: 1034 | BL37: 413 | BM37: 0 | BN37: 0 | BO37: 0.1643026 | BP37: 23-08-2026 19:35:00 | BU37: 2 | BV37: BOM-MAA | CA37: 413 | CB37: TeamLease Edtech Limited | CC37: 29AAPCS2871R1Z7 | CE37: M | CF37: '11804239608231725 | CJ37: T17642 | CK37: L8
A38: DA26/185880 | B38: 23-AUG-2026 | C38: 23-AUG-2026 | D38: University Bd | E38: Bengaluru | F38: MS. DEEPTI DEEPTI | G38: T17404 | I38: 61-MUM-USE | K38: 27-08-2026 12:00:00 | L38: Jaipur-New Delhi | M38: Air India | N38: AI-0430 | O38: Economy | P38: 5808985901 | Q38: 4080 | R38: 0 | S38: 1450 | T38: 204 | U38: 5734 | V38: 75 | W38: MR. SHANTANU ROOJ | X38: Approved | Y38: 23-AUG-2026 | Z38: 13:07 | AA38: FLOWN | AB38: Teamlease Services Ltd | AC38: TLEdtech | AD38: 200118054129 | AE38: 6900149 | AF38: Assistant General Manager | AG38: Round Trip | AH38: Domestic | AI38: L8 | AJ38: deepti.thakur@teamlease.com | AK38: W | AL38: 299 | AM38: 170 | AN38: 44881914 | AO38: 23-AUG-2026 | AP38: 13:03 | AR38: CORPORATE | AS38: Official | AT38: Original | AY38: 9899203334 | AZ38: 29AAPCS2871R1Z7 | BA38: Karnataka | BB38: '0985808985901 | BC38: DSRJ3S | BD38: T004S | BE38: - | BF38: 996425 | BG38: 27-08-202/ | BH38: Ms. Deepti DEEPTI | BI38: T17404 | BJ38: 233 | BL38: 0 | BM38: 0 | BN38: 0 | BO38: 0.0370237 | BP38: 27-08-2026 13:10:00 | BU38: 4 | BV38: JAI-DEL | CA38: 204 | CB38: TeamLease Edtech Limited | CC38: 29AAPCS2871R1Z7 | CE38: F | CF38: '11805412908271200 | CJ38: SG0014 | CK38: LST
A39: DW26/820993 | B39: 23-AUG-2026 | C39: 23-AUG-2026 | D39: University Bd | E39: Bengaluru | F39: MS. DEEPTI DEEPTI | G39: T17404 | I39: 61-MUM-USE | K39: 26-08-2026 07:40:00 | L39: New Delhi-Jaipur | M39: Indigo | N39: 6E-6190 | O39: Economy | P39: FGRS4R | Q39: 3900 | R39: 0 | S39: 874 | T39: 195 | U39: 4969 | V39: 75 | W39: MR. SHANTANU ROOJ | X39: Approved | Y39: 23-AUG-2026 | Z39: 13:07 | AA39: FLOWN | AB39: Teamlease Services Ltd | AC39: TLEdtech | AD39: 200118054128 | AE39: 6900149 | AF39: Assistant General Manager | AG39: Round Trip | AH39: Domestic | AI39: L8 | AJ39: deepti.thakur@teamlease.com | AK39: L | AL39: 275 | AM39: 0 | AN39: 44881914 | AO39: 23-AUG-2026 | AP39: 13:03 | AR39: CORPORATE | AS39: Official | AT39: Original | AY39: 9899203334 | AZ39: 29AAPCS2871R1Z7 | BA39: Karnataka | BB39: FGRS4R | BC39: FGRS4R | BD39: T004S | BE39: - | BF39: 996425 | BG39: 26-08-202/ | BH39: Ms. Deepti DEEPTI | BI39: T17404 | BJ39: 233 | BL39: 195 | BM39: 0 | BN39: 0 | BO39: 0.0370237 | BP39: 26-08-2026 08:40:00 | BU39: 3 | BV39: DEL-JAI | CA39: 195 | CB39: TeamLease Edtech Limited | CC39: 29AAPCS2871R1Z7 | CE39: F | CF39: '11805412808260740 | CJ39: SG0014 | CK39: LST
A40: DW26/832334 | B40: 25-AUG-2026 | C40: 25-AUG-2026 | D40: University Bd | E40: Bengaluru | F40: MR. KHUNJAMAYUM DAVID SINGH | G40: T17743 | I40: 61-MUM-USE | K40: 29-08-2026 16:15:00 | L40: Mysore-Hyderabad | M40: Indigo | N40: 6E-7141 | O40: Economy | P40: JC142D | Q40: 12780 | R40: 0 | S40: 475 | T40: 639 | U40: 13894 | V40: 75 | W40: MR. SHANTANU ROOJ | X40: Approved | Y40: 25-AUG-2026 | Z40: 11:04 | AA40: FLOWN | AB40: Teamlease Services Ltd | AC40: TLEdtech | AD40: 200118081816 | AE40: 7442895 | AF40: Regional Head | AG40: Round Trip | AH40: Domestic | AI40: L8 | AJ40: david.singh@teamlease.com | AK40: C | AL40: 400 | AM40: 0 | AN40: 44918655 | AO40: 25-AUG-2026 | AP40: 08:19 | AR40: CORPORATE | AS40: Official | AT40: Original | AY40: 9205927758 | AZ40: 29AAPCS2871R1Z7 | BA40: Karnataka | BB40: JC142D | BC40: JC142D | BD40: T004S | BE40: - | BF40: 996425 | BG40: 29-08-202/ | BH40: Mr. Satyavan Sawant | BI40: T17247 | BJ40: 580 | BL40: 0 | BM40: 0 | BN40: 0 | BO40: 0.092162 | BP40: 29-08-2026 18:05:00 | BU40: 4 | BV40: MYQ-HYD | CA40: 639 | CB40: TeamLease Edtech Limited | CC40: 29AAPCS2871R1Z7 | CE40: M | CF40: '11808181608291615 | CJ40: SG0014 | CK40: LST
A41: DW26/833735 | B41: 25-AUG-2026 | C41: 25-AUG-2026 | D41: University Bd | E41: Bengaluru | F41: MR. KHUNJAMAYUM DAVID SINGH | G41: T17743 | I41: 61-MUM-USE | K41: 28-08-2026 14:00:00 | L41: Hyderabad-Mysore | M41: Indigo | N41: 6E-7126 | O41: Economy | P41: RBH4UJ | Q41: 7680 | R41: 0 | S41: 1114 | T41: 384 | U41: 9178 | V41: 75 | W41: MR. SHANTANU ROOJ | X41: Approved | Y41: 25-AUG-2026 | Z41: 11:04 | AA41: FLOWN | AB41: Teamlease Services Ltd | AC41: TLEdtech | AD41: 200118081815 | AE41: 7442895 | AF41: Regional Head | AG41: Round Trip | AH41: Domestic | AI41: L8 | AJ41: david.singh@teamlease.com | AK41: M | AL41: 400 | AM41: 0 | AN41: 44918655 | AO41: 25-AUG-2026 | AP41: 08:19 | AR41: CORPORATE | AS41: Official | AT41: Original | AY41: 9205927758 | AZ41: 29AAPCS2871R1Z7 | BA41: Karnataka | BB41: RBH4UJ | BC41: RBH4UJ | BD41: T004S | BE41: - | BF41: 996425 | BG41: 28-08-202/ | BH41: Mr. Satyavan Sawant | BI41: T17247 | BJ41: 580 | BL41: 384 | BM41: 0 | BN41: 0 | BO41: 0.092162 | BP41: 28-08-2026 15:55:00 | BU41: 3 | BV41: HYD-MYQ | CA41: 384 | CB41: TeamLease Edtech Limited | CC41: 29AAPCS2871R1Z7 | CE41: M | CF41: '11808181508281400 | CJ41: SG0014 | CK41: LST
...

Sheet MISCELLANEOUS DEBIT
A1: Domestic Air Travel Miscellaneous Statement for the period 16-08-2026 to 31-08-2026
A3: Reference No. | B3: Reference Date | C3: Booking Date | D3: Department | E3: Location | F3: Passenger Name | G3: Employee Code | H3: Cost Center | I3: Cost Code | J3: Product Line | K3: Travel Date | L3: Sector | M3: Airline | N3: Flight No. | O3: Class | P3: Ticket No. | Q3: Total Fare | R3: Travel Management Fee | S3: Approver Name | T3: Approval Status | U3: Approval Date | V3: Approval Time | W3: Flown Status | X3: Corporate | Y3: Business Unit | Z3: Booking Reference No. | AA3: Trip Unique ID | AB3: Designation | AC3: Type Of Journey | AD3: Type Of Travel | AE3: Job Band | AF3: Passenger Email Id | AG3: Booking Code | AH3: YQ | AI3: YR | AJ3: Request No. | AK3: Request Created Date | AL3: Request Created Time | AM3: Trip Title | AN3: Fare Type | AO3: Purpose of Visit | AP3: Reissue Status | AQ3: Second Approver Name | AR3: Second Approval Status | AS3: Second Approval Date | AT3: Second Approval Time | AU3: Contact No. | AV3: GST No. | AW3: GST State | AX3: Service | AY3: Main Inv. No. | AZ3: Main Inv. Date | BA3: XL Code | BB3: HSN Code | BC3: Only Travel Date | BD3: TR ID | BE3: Debit Cost Code | BF3: Referred by | BG3: GL Code | BH3: Job Type | BI3: SAP / HR Company Code | BJ3: Adani Legal Entity GST Number | BK3: Job Reason | BL3: APPROVER_EMP_ID | BM3: APPROVER_BAND
A4: MW26/42976 | B4: 20-AUG-2026 | C4: 19/08/2026 | D4: University B2C | E4: Bengaluru | F4: Mr. UDITENDU BOSE | G4: SG0320 | H4: 3701618 | I4: 62-MUM-SSS | K4: 23/08/2026 11:35 | L4: Kolkata-Mumbai | M4: Indigo | N4: 6E-5288 | O4: Economy | P4: KDJR9N | Q4: 428 | R4: 80 | S4: Mr.ShantanuRooj | T4: Approved | U4: 19-08-2026 12:00:00 AM | W4: FLOWN | X4: Teamlease Services Ltd | Y4: TEAMLEASE EDTECH LIMITED | Z4: 200117999595 | AA4: 1388087 | AB4: Vice President - Consumer Sales | AC4: One Way | AD4: Domestic | AE4: L10 | AF4: uditendu.bose@teamlease.com | AG4: R | AH4: 0 | AI4: 0 | AJ4: 44806175 | AK4: 19-AUG-2026 | AL4: 16:55 | AN4: CORPORATE | AO4: Official | AP4: Original | AU4: 9971252225 | AV4: 29AAPCS2871R1Z7 | AW4: Karnataka | AX4: Seat Charges | AY4: DW26/799416 | AZ4: 19-08-2026 12:00:00 AM | BA4: T004S | BB4: 9963 | BC4: 23/08/2026 | BI4: TeamLease Edtech Limited | BJ4: 29AAPCS2871R1Z7 | BL4: SG0014 | BM4: LST
A5: DD26/6247 | B5: 19-AUG-2026 | C5: 19/08/2026 | D5: University B2C | E5: Bengaluru | F5: BOSE/UDITENDU MR | G5: SG0320 | H5: 3701618 | I5: 62-MUM-SSS | K5: 27-08-2026 12:00:00 AM | L5: Mumbai-Kolkata | M5: AIR INDIA LTD. | N5: AI2771 | O5: Economy | P5: 1946780348 | Q5: 975 | R5: 80 | S5: Mr.ShantanuRooj,Mr.ShantanuRooj | T5: Approved,Approved | U5: 19-AUG-2026,19-AUG-2026 | W5: FLOWN | X5: Teamlease Services Ltd | Y5: TEAMLEASE EDTECH LIMITED | Z5: 200117997991 | AA5: 1388087 | AB5: Vice President - Consumer Sales | AC5: Round Trip | AD5: Domestic | AE5: L10 | AF5: uditendu.bose@teamlease.com | AH5: 0 | AI5: 0 | AJ5: 44798324 | AK5: 19-AUG-2026 | AL5: 13:59 | AN5: CORPORATE | AO5: Official | AP5: Original | AU5: 9971252225 | AV5: 29AAPCS2871R1Z7 | AW5: Karnataka | AY5: DA26/181266 | AZ5: 19-08-2026 12:00:00 AM | BA5: T004S | BB5: 9963 | BC5: 27/08/2026 | BI5: TeamLease Edtech Limited | BJ5: 29AAPCS2871R1Z7 | BL5: SG0014,SG0014 | BM5: LST,LST
A6: DD26/6814 | B6: 30-AUG-2026 | C6: 30/08/2026 | D6: University B2C | E6: Bengaluru | F6: BOSE/UDITENDU MR | G6: SG0320 | H6: 3701618 | I6: 62-MUM-SSS | K6: 31-08-2026 12:00:00 AM | L6: Kolkata-New Delhi | M6: AIR INDIA LTD. | N6: AI1805 | O6: Economy | P6: 1946816928 | Q6: 225 | R6: 80 | S6: Mr.ShantanuRooj | T6: Approved | U6: 28-AUG-2026 | W6: FLOWN | X6: Teamlease Services Ltd | Y6: TEAMLEASE EDTECH LIMITED | Z6: 200118130772 | AA6: 1388087 | AB6: Vice President - Consumer Sales | AC6: One Way | AD6: Domestic | AE6: L10 | AF6: uditendu.bose@teamlease.com | AH6: 0 | AI6: 0 | AJ6: 44990409 | AK6: 28-AUG-2026 | AL6: 08:28 | AN6: CORPORATE | AO6: Official | AP6: Original | AU6: 9971252225 | AV6: 29AAPCS2871R1Z7 | AW6: Karnataka | AY6: DA26/192415 | AZ6: 28-08-2026 12:00:00 AM | BA6: T004S | BB6: 9963 | BC6: 31/08/2026 | BI6: TeamLease Edtech Limited | BJ6: 29AAPCS2871R1Z7 | BL6: SG0014 | BM6: LST
A7: Total | Q7: =SUM(Q4:Q6) -> 1628 | R7: =SUM(R4:R6) -> 240

Sheet RAIL DEBIT
A1: Rail Travel Statement for the period 16-08-2026 to 31-08-2026
A3: Reference No. | B3: Reference Date | C3: Booking Date | D3: Department | E3: Location | F3: Passenger Name | G3: Employee Code | H3: Cost Center | I3: Cost Code | J3: Travel Date | K3: Sector | L3: Train | M3: Class | N3: PNR No. | O3: Total Fare | P3: Travel Management Fee | Q3: Approver Name | R3: Approval Status | S3: Corporate | T3: Business Unit | U3: Booking Reference No. | V3: Trip Unique ID | W3: Rail Transation ID | X3: Rail Portal Code | Y3: Self Arranged | Z3: Request No. | AA3: Request Created Date | AB3: Purpose of Visit | AC3: Train Quota | AD3: Sector Short | AE3: Trip Title | AF3: State Name | AG3: XL Code | AH3: Job Band | AI3: KM | AJ3: Client Req No | AK3: PROJECT | AL3: TR ID | AM3: Debit Cost Code | AN3: Function | AO3: Referred By | AP3: GL Code | AQ3: Job Type | AR3: SAP / HR Company Code | AS3: Adani Legal Entity GST Number | AT3: Location Code | AU3: Gender | AV3: Unique ID | AW3: Gst Invoice No | AX3: Supplier GST No | AY3: Taxable Amt | AZ3: CGST Rate | BA3: CGST Amt | BB3: SGST UGST Rate | BC3: SGST UGST Amt | BD3: IGST Rate | BE3: IGST Amt | BF3: Total Tax | BG3: Job Reason | BH3: APPROVER_GRADE | BI3: APPROVER_EMPID | BJ3: GST_NO
A4: LW26/154872 | B4: 16-AUG-2026 | C4: 16-AUG-2026 | D4: University B2C | E4: Bengaluru | F4: MR. PREETISH GUPTA | G4: SG0516 | H4: 3701618 | I4: 62-MUM-SSS | J4: 17-AUG-2026 | K4: BORIVALI - BVI-GANDHINAGAR CAP - GNC | L4: ADI SHATABDI EXP | M4: CC | N4: 8152258307 | O4: 1462 | P4: 300 | Q4: Mr. UDITENDU BOSE | R4: Approved | S4: Teamlease Services Ltd | T4: TLEdtech | U4: 600117938493 | V4: Official | W4: 8152258307 | X4: EAKDANTA ENTERPRISES | Y4: N | Z4: 44714065 | AA4: 16-08-2026 09:16:03 AM | AB4: Official | AC4: TATKAL | AD4: BVI-GNC | AE4: Rail Service | AF4: Karnataka | AG4: T004S | AH4: L9 | AI4: 462 | AK4: - | AR4: TeamLease Edtech Limited | AS4: 29AAPCS2871R1Z7 | AU4: M | AV4: '11793849301388534 | AW4: 0 | AX4: 0 | AY4: 0 | AZ4: 0 | BA4: 0 | BB4: 0 | BC4: 0 | BD4: 0 | BE4: 0 | BF4: 0 | BH4: L10 | BI4: SG0320 | BJ4: 29AAPCS2871R1Z7
A5: LW26/156223 | B5: 17-AUG-2026 | C5: 17-AUG-2026 | D5: University Bd | E5: Bengaluru | F5: MR. NAKUL JOSHI | G5: T15226 | I5: 61-MUM-USE | J5: 18-AUG-2026 | K5: MUMBAI CENTRAL - MMCT-VADODARA JN - BRC | L5: ADI SHATABDI EX | M5: CC | N5: 8833051579 | O5: 1193 | P5: 300 | Q5: Ms. Deepti DEEPTI | R5: Approved | S5: Teamlease Services Ltd | T5: TLEdtech | U5: 600117949444 | V5: Official | W5: 100006776270404 | X5: GUPTA TRAVELS PUNE | Y5: N | Z5: 44666082 | AA5: 13-08-2026 04:42:02 PM | AB5: Official | AC5: TATKAL | AD5: MMCT-BRC | AE5: Rail Service | AF5: Karnataka | AG5: T004S | AH5: L7 | AI5: 392 | AK5: - | AR5: TeamLease Edtech Limited | AS5: 29AAPCS2871R1Z7 | AU5: M | AV5: '11794944402413020 | AW5: 100006776270404 | AX5: 100006776270404 | AY5: 0 | AZ5: 0 | BA5: 0 | BB5: 0 | BC5: 0 | BD5: 0 | BE5: 0 | BF5: 0 | BH5: L8 | BI5: T17404 | BJ5: 29AAPCS2871R1Z7
A6: LW26/155606 | B6: 17-AUG-2026 | C6: 17-AUG-2026 | D6: University B2C | E6: Bengaluru | F6: MR. MALLA HARI KRISHNA NA | G6: T14999 | I6: 62-MUM-USP | J6: 18-AUG-2026 | K6: VIJAYAWADA JN - BZA-ANANTAPUR - ATP | L6: MTM DMM EXP | M6: 3A | N6: 4343122003 | O6: 1027 | P6: 100 | Q6: Mr. VENKATA SWAMI NAIDU SURISETTY | R6: Approved | S6: Teamlease Services Ltd | T6: TLEdtech | U6: 600117954902 | V6: Official | W6: 4343122003 | X6: AKHTAR HOSSAIN | Y6: N | Z6: 44732008 | AA6: 17-08-2026 12:17:48 PM | AB6: Official | AC6: GENERAL | AD6: BZA-ATP | AE6: Rail Service | AF6: Karnataka | AG6: T004S | AH6: L6 | AI6: 581 | AK6: - | AR6: TeamLease Edtech Limited | AS6: 29AAPCS2871R1Z7 | AU6: M | AV6: '11795490201919861 | AW6: PS26434312200311 | AX6: 07AAAGM0289C1ZL | AY6: 900 | AZ6: 2.5 | BA6: 0 | BB6: 5 | BC6: 0 | BD6: 5 | BE6: 5.4 | BF6: 5.4 | BH6: L8 | BI6: T16637 | BJ6: 29AAPCS2871R1Z7
A7: LW26/155922 | B7: 17-AUG-2026 | C7: 17-AUG-2026 | D7: University B2C | E7: Bengaluru | F7: MR. MALLA HARI KRISHNA NA | G7: T14999 | I7: 62-MUM-USP | J7: 18-AUG-2026 | K7: VISHAKAPATNAM - VSKP-VIJAYAWADA JN - BZA | L7: RATNANCHAL SF EX | M7: 2S | N7: 6948256362 | O7: 219 | P7: 300 | Q7: Mr. VENKATA SWAMI NAIDU SURISETTY | R7: Approved | S7: Teamlease Services Ltd | T7: TLEdtech | U7: 600117954881 | V7: Official | W7: 6948256362 | X7: BHARAT TRAVELS | Y7: N | Z7: 44732008 | AA7: 17-08-2026 12:17:48 PM | AB7: Official | AC7: TATKAL | AD7: VSKP-BZA | AE7: Rail Service | AF7: Karnataka | AG7: T004S | AH7: L6 | AI7: 350 | AK7: - | AR7: TeamLease Edtech Limited | AS7: 29AAPCS2871R1Z7 | AU7: M | AV7: '11795488101919861 | AW7: PS26694825636211 | AX7: 07AAAGM0289C1ZL | AY7: 180 | AZ7: 0 | BA7: 0 | BB7: 0 | BC7: 0 | BD7: 0 | BE7: 0 | BF7: 0 | BH7: L8 | BI7: T16637 | BJ7: 29AAPCS2871R1Z7
A8: LW26/156901 | B8: 17-AUG-2026 | C8: 17-AUG-2026 | D8: University B2C | E8: Bengaluru | F8: MR. MALLA HARI KRISHNA NA | G8: T14999 | I8: 62-MUM-USP | J8: 20-AUG-2026 | K8: NELLORE - NLR-VIJAYAWADA JN - BZA | L8: SIMHAPURI SF EX | M8: 3E | N8: 4763105013 | O8: 645 | P8: 100 | Q8: Mr. VENKATA SWAMI NAIDU SURISETTY | R8: Approved | S8: Teamlease Services Ltd | T8: TLEdtech | U8: 600117963586 | V8: Official | W8: 100006777333268 | X8: GUPTA TRAVELS PUNE | Y8: N | Z8: 44746254 | AA8: 17-08-2026 05:07:16 PM | AB8: Official | AC8: GENERAL | AD8: NLR-BZA | AE8: Rail Service | AF8: Karnataka | AG8: T004S | AH8: L6 | AI8: 255 | AK8: - | AR8: TeamLease Edtech Limited | AS8: 29AAPCS2871R1Z7 | AU8: M | AV8: '11796358601919861 | AW8: PS26476310501311 | AX8: 07AAAGM0289C1ZL | AY8: 538 | AZ8: 0 | BA8: 0 | BB8: 0 | BC8: 0 | BD8: 5 | BE8: 0 | BF8: 0 | BH8: L8 | BI8: T16637 | BJ8: 29AAPCS2871R1Z7
A9: LW26/157627 | B9: 18-AUG-2026 | C9: 18-AUG-2026 | D9: University Bd | E9: Bengaluru | F9: MR. ASHUTOSH DUBEY | G9: T17010 | I9: 61-MUM-USE | J9: 25-AUG-2026 | K9: KAMAKHYA - KYQ-PATNA JN - PNBE | L9: CAPITAL EXPRESS | M9: 3A | N9: 6608204369 | O9: 1411 | P9: 100 | Q9: Mr. MAHESH KUMAR | R9: Approved | S9: Teamlease Services Ltd | T9: TLEdtech | U9: 600117975205 | V9: Official | W9: 6608204369 | X9: Akbar - 1 | Y9: N | Z9: 44764099 | AA9: 18-08-2026 12:04:50 PM | AB9: Official | AC9: GENERAL | AD9: KYQ-PNBE | AE9: Rail Service | AF9: Karnataka | AG9: T004S | AH9: L7 | AI9: 980 | AK9: - | AR9: TeamLease Edtech Limited | AS9: 29AAPCS2871R1Z7 | AU9: M | AV9: '11797520506003228 | AW9: PS26660820436911 | AX9: 07AAAGM0289C1ZL | AY9: 1262 | AZ9: 0 | BA9: 0 | BB9: 0 | BC9: 0 | BD9: 5 | BE9: 62.95 | BF9: 62.95 | BH9: L8 | BI9: T15604 | BJ9: 29AAPCS2871R1Z7
A10: LW26/162124 | B10: 21-AUG-2026 | C10: 21-AUG-2026 | D10: University B2C | E10: Bengaluru | F10: MR. ABHISHEK MATONDKAR | G10: T17720 | I10: 62-MUM-SSS | J10: 22-AUG-2026 | K10: BORIVALI - BVI-SURAT - ST | L10: ADI SHATABDI EXP | M10: CC | N10: 8940700511 | O10: 932 | P10: 300 | Q10: MR. Preetish Gupta | R10: Approved | S10: Teamlease Services Ltd | T10: TLEdtech | U10: 600118029094 | V10: Official | W10: 8940700511 | X10: SIDDHIVINAYAK TOUR & TRAVELS | Y10: N | Z10: 44835799 | AA10: 20-08-2026 06:23:06 PM | AB10: Official | AC10: TATKAL | AD10: BVI-ST | AE10: Rail Service | AF10: Karnataka | AG10: T004S | AH10: L5 | AI10: 233 | AK10: - | AR10: TeamLease Edtech Limited | AS10: 29AAPCS2871R1Z7 | AU10: M | AV10: '11802909407403372 | AW10: PS26894070051111 | AX10: 07AAAGM0289C1ZL | AY10: 687 | AZ10: 0 | BA10: 0 | BB10: 0 | BC10: 0 | BD10: 5 | BE10: 34.35 | BF10: 34.35 | BH10: L9 | BI10: SG0516 | BJ10: 29AAPCS2871R1Z7
